2024-05-01 10:32:10 [INFO] Starting the application
2024-05-01 10:32:11 [ERROR] Exception occurred:
Traceback (most recent call last):
  File "main.py", line 10, in <module>
    raise ValueError("Something went wrong")
ValueError: Something went wrong

